Workbook
Name UPDATE: 'Data Sheet'!$E$1

Sheet Teaser
B2: ='Profit & Loss'!A1&" - One Page Profile" -> MARUTI SUZUKI INDIA LTD - One Page Profile
C4: =Input!B6 -> Maruti Suzuki India Limited is the Indian subsidiary of Japanese automaker Suzuki Motor Corporation. It is the largest automobile manufacturer in India, specialising in small cars. The company was established by the Government of India as Maruti Udyog Limited in February 1981 as a joint venture with Suzuki, the latter becoming the first Japanese automaker, as well as the first major foreign automaker, to invest in India
B5: INR (Crs)
B6: Key Financial Metrics | C6: ='Profit & Loss'!G3 -> 44286 | D6: ='Profit & Loss'!H3 -> 44651 | E6: ='Profit & Loss'!I3 -> 45016 | F6: ='Profit & Loss'!J3 -> 45382 | G6: ='Profit & Loss'!K3 -> 45747 | I6: Share Price - 5Y
B8: Total Sales | C8: ='Profit & Loss'!G4 -> 70372 | D8: ='Profit & Loss'!H4 -> 88329.8 | E8: ='Profit & Loss'!I4 -> 117571.3 | F8: ='Profit & Loss'!J4 -> 141858.2 | G8: ='Profit & Loss'!K4 -> 152913
B9: Sales Growth (y-o-y) | C9: ='Profit & Loss'!G28 -> -0.06989162 | D9: ='Profit & Loss'!H28 -> 0.25518388 | E9: ='Profit & Loss'!I28 -> 0.33104909 | F9: ='Profit & Loss'!J28 -> 0.20657167 | G9: ='Profit & Loss'!K28 -> 0.077928523
B10: Gross Profit Margins (%) | C10: ='Profit & Loss'!G30 -> 0.26907293 | D10: ='Profit & Loss'!H30 -> 0.23340028 | E10: ='Profit & Loss'!I30 -> 0.24327366 | F10: ='Profit & Loss'!J30 -> 0.27765332 | G10: ='Profit & Loss'!K30 -> 0.26106479
B11: EBITDA Margins (%) | C11: ='Profit & Loss'!G31 -> 0.076885693 | D11: ='Profit & Loss'!H31 -> 0.065119586 | E11: ='Profit & Loss'!I31 -> 0.093808608 | F11: ='Profit & Loss'!J31 -> 0.13130224 | G11: ='Profit & Loss'!K31 -> 0.1322556
B12: EBIT Margins (%) | C12: ='Profit & Loss'!G32 -> 0.033770534 | D12: ='Profit & Loss'!H32 -> 0.033544738 | E12: ='Profit & Loss'!I32 -> 0.069774681 | F12: ='Profit & Loss'!J32 -> 0.094252571 | G12: ='Profit & Loss'!K32 -> 0.09557984
B13: Net Profit Margins (%) | C13: ='Profit & Loss'!G33 -> 0.062369977 | D13: ='Profit & Loss'!H33 -> 0.043920625 | E13: ='Profit & Loss'!I33 -> 0.069838472 | F13: ='Profit & Loss'!J33 -> 0.095082272 | G13: ='Profit & Loss'!K33 -> 0.09482647
B14: Earning Per Share (In Rs) | C14: ='Profit & Loss'!G13 -> 145.28633 | D14: ='Profit & Loss'!H13 -> 128.41774 | E14: ='Profit & Loss'!I13 -> 271.79742 | F14: ='Profit & Loss'!J13 -> 429.01399 | G14: ='Profit & Loss'!K13 -> 461.20229
B15: EPS Growth (y-o-y) | C15: ='Profit & Loss'!G34 -> -0.22672657 | D15: ='Profit & Loss'!H34 -> -0.11610581 | E15: ='Profit & Loss'!I34 -> 1.1165099 | F15: ='Profit & Loss'!J34 -> 0.57843293 | G15: ='Profit & Loss'!K34 -> 0.075028543
B16: Dividend Per Share | C16: ='Profit & Loss'!G35 -> 44.985104 | D16: ='Profit & Loss'!H35 -> 59.980139 | E16: ='Profit & Loss'!I35 -> 89.970209 | F16: ='Profit & Loss'!J35 -> 125 | G16: ='Profit & Loss'!K35 -> 135
B17: DPS Growth (y-o-y) | C17: ='Profit & Loss'!G36 -> -0.25 | D17: ='Profit & Loss'!H36 -> 0.33333333 | E17: ='Profit & Loss'!I36 -> 0.5 | F17: ='Profit & Loss'!J36 -> 0.38934879 | G17: ='Profit & Loss'!K36 -> 0.08
B19: Key Financial Ratio | C19: =C6 -> 44286 | D19: =D6 -> 44651 | E19: =E6 -> 45016 | F19: =F6 -> 45382 | G19: =G6 -> 45747 | I19: Volume - 5Y
B21: Price to Earnings | C21: ='Profit & Loss'!G14 -> 47.2116 | D21: ='Profit & Loss'!H14 -> 58.880493 | E21: ='Profit & Loss'!I14 -> 30.508568 | F21: ='Profit & Loss'!J14 -> 29.370487 | G21: ='Profit & Loss'!K14 -> 24.982855
B22: EV/EBITDA | C22: ='Profit & Loss'!G42 -> 37.835033 | D22: ='Profit & Loss'!H42 -> 39.25768 | E22: ='Profit & Loss'!I42 -> 22.822286 | F22: ='Profit & Loss'!J42 -> 21.123154 | G22: ='Profit & Loss'!K42 -> 17.88952
B23: EV/Sales | C23: ='Profit & Loss'!G43 -> 2.9089728 | D23: ='Profit & Loss'!H43 -> 2.5564438 | E23: ='Profit & Loss'!I43 -> 2.1409268 | F23: ='Profit & Loss'!J43 -> 2.7735175 | G23: ='Profit & Loss'!K43 -> 2.3659891
B24: Price to Book Value | C24: ='Profit & Loss'!G44 -> 3.9469345 | D24: ='Profit & Loss'!H44 -> 4.1281841 | E24: ='Profit & Loss'!I44 -> 4.0540635 | F24: ='Profit & Loss'!J44 -> 4.6260335 | G24: ='Profit & Loss'!K44 -> 3.7640978
B25: Return on Equity (%) | C25: ='Balance Sheet'!G23 -> 0.083600949 | D25: ='Balance Sheet'!H23 -> 0.070111235 | E25: ='Balance Sheet'!I23 -> 0.13288278 | F25: ='Balance Sheet'!J23 -> 0.15750619 | G25: ='Balance Sheet'!K23 -> 0.15066724
B26: Return on Capital Employed (%) | C26: ='Balance Sheet'!G24 -> 0.10566785 | D26: ='Balance Sheet'!H24 -> 0.088672387 | E26: ='Balance Sheet'!I24 -> 0.17694129 | F26: ='Balance Sheet'!J24 -> 0.23681324 | G26: ='Balance Sheet'!K24 -> 0.217641
B28: Top 10 Shareholders | C28: =Input!X9 -> N. Shares (in Crs) | E28: =Input!Y9 -> (%) holding | F28: =Input!Z9 -> Market Value (in Crs.) | I28: Shareholding Pattern
B29: =Input!W10 -> Suzuki Motor Corporation | C29: =Input!X10 -> 1832.4648 | E29: =Input!Y10 -> 0.5828 | F29: =Input!Z10 -> 23145862
B30: =Input!W11 -> LICI ULIP-Growth Fund | C30: =Input!X11 -> 135.17739 | E30: =Input!Y11 -> 0.043 | F30: =Input!Z11 -> 1707425.6
B31: =Input!W12 -> ICICI N50 Equal Weight Index Fund | C31: =Input!X12 -> 99.48721 | E31: =Input!Y12 -> 0.0316 | F31: =Input!Z12 -> 1256622.9
B32: =Input!W13 -> SBI ESG Exclusionary Strategy Fund | C32: =Input!X13 -> 72.03103 | E32: =Input!Y13 -> 0.0229 | F32: =Input!Z13 -> 909823.94
B33: =Input!W14 -> HDFC Trustee Company Ltd-Flexi Fund | C33: =Input!X14 -> 67.57821 | E33: =Input!Y14 -> 0.0215 | F33: =Input!Z14 -> 853580.37
B34: =Input!W15 -> NPS UTI Pension Fund Ltd-Scheme Cent | C34: =Input!X15 -> 43.68427 | E34: =Input!Y15 -> 0.0139 | F34: =Input!Z15 -> 551776.01
B35: =Input!W16 -> Kotak Balanced Advantage Fund | C35: =Input!X16 -> 38.74829 | E35: =Input!Y16 -> 0.0123 | F35: =Input!Z16 -> 489429.65
B36: =Input!W17 -> UTI Manufacturing Index Fund | C36: =Input!X17 -> 36.43827 | E36: =Input!Y17 -> 0.0116 | F36: =Input!Z17 -> 460251.79
B37: =Input!W18 -> Nippon India Large Cap Fund | C37: =Input!X18 -> 30.25 | E37: =Input!Y18 -> 0.0096 | F37: =Input!Z18 -> 382087.75
B38: =Input!W19 -> Axis Bluechip Fund | C38: =Input!X19 -> 28.1 | E38: =Input!Y19 -> 0.0089 | F38: =Input!Z19 -> 354931.1
B40: Managerial Remuneration | C40: Designation | E40: Remuneration | F40: X of Median Salary | I40: Capital Structure
B42: Mr. Hisashi Takeuchi | C42: MD & CEO | E42: 56901817 | F42: 32.86 | I42: Share Price as on | K42: ='Data Sheet'!B8 -> 12631
B43: Mr. Kenichiro Toyofuku | C43: Director (Sus) | E43: 42199600 | F43: 24.37 | I43: No. of Share Outstanding | K43: ='Data Sheet'!B6 -> 31.440257
B44: Mr. Kazunari Yamaguchi | C44: Director (Prod) | E44: 42199600 | F44: 24.37 | I44: Market Capitalization | K44: =K42*K43 -> 397121.89
I45: Less: Cash & Equivalents | K45: ='Data Sheet'!K69*-1 -> -552.9
I46: Add: Total Debt | K46: ='Balance Sheet'!K6 -> 87
I47: Add: Minority Interest | K47: 0
I48: Enterprise Value | K48: =SUM(K44:K47) -> 396655.99
...

Sheet DATA>

Sheet Profit & Loss
A1: ='Data Sheet'!B1 -> MARUTI SUZUKI INDIA LTD | H1: =UPDATE | M1: SCREENER.IN
A3: Narration | B3: ='Data Sheet'!B16 -> 42460 | C3: ='Data Sheet'!C16 -> 42825 | D3: ='Data Sheet'!D16 -> 43190 | E3: ='Data Sheet'!E16 -> 43555 | F3: ='Data Sheet'!F16 -> 43921 | G3: ='Data Sheet'!G16 -> 44286 | H3: ='Data Sheet'!H16 -> 44651 | I3: ='Data Sheet'!I16 -> 45016 | ... K3: ='Data Sheet'!K16 -> 45747 | L3: Trailing | M3: Best Case | N3: Worst Case
A4: Sales | B4: ='Data Sheet'!B17 -> 57589 | C4: ='Data Sheet'!C17 -> 68085 | D4: ='Data Sheet'!D17 -> 79809.4 | E4: ='Data Sheet'!E17 -> 86068.5 | F4: ='Data Sheet'!F17 -> 75660 | G4: ='Data Sheet'!G17 -> 70372 | H4: ='Data Sheet'!H17 -> 88329.8 | I4: ='Data Sheet'!I17 -> 117571.3 | ... K4: ='Data Sheet'!K17 -> 152913 | L4: =SUM(Quarters!H4:K4) -> 171773.6 | M4: =$K4+M23*K4 -> 183607.38 | N4: =$K4+N23*L4 -> 169633.56
A5: Expenses | B5: =SUM('Data Sheet'!B18,'Data Sheet'!B20:B24, -1*'Data Sheet'!B19) -> 48564.9 | C5: =SUM('Data Sheet'!C18,'Data Sheet'!C20:C24, -1*'Data Sheet'!C19) -> 57663.7 | D5: =SUM('Data Sheet'!D18,'Data Sheet'!D20:D24, -1*'Data Sheet'!D19) -> 67691.5 | E5: =SUM('Data Sheet'!E18,'Data Sheet'!E20:E24, -1*'Data Sheet'!E19) -> 75012.2 | F5: =SUM('Data Sheet'!F18,'Data Sheet'!F20:F24, -1*'Data Sheet'!F19) -> 68305 | G5: =SUM('Data Sheet'!G18,'Data Sheet'!G20:G24, -1*'Data Sheet'!G19) -> 64961.4 | H5: =SUM('Data Sheet'!H18,'Data Sheet'!H20:H24, -1*'Data Sheet'!H19) -> 82577.8 | I5: =SUM('Data Sheet'!I18,'Data Sheet'!I20:I24, -1*'Data Sheet'!I19) -> 106542.1 | ... K5: =SUM('Data Sheet'!K18,'Data Sheet'!K20:K24, -1*'Data Sheet'!K19) -> 132689.4 | L5: =SUM(Quarters!H5:K5) -> 151647.9 | M5: =M4-M6 -> 161397.27 | N5: =N4-N6 -> 151500.6
A6: Operating Profit | B6: =B4-B5 -> 9024.1 | C6: =C4-C5 -> 10421.3 | D6: =D4-D5 -> 12117.9 | E6: =E4-E5 -> 11056.3 | F6: =F4-F5 -> 7355 | G6: =G4-G5 -> 5410.6 | H6: =H4-H5 -> 5752 | I6: =I4-I5 -> 11029.2 | ... K6: =K4-K5 -> 20223.6 | L6: =SUM(Quarters!H6:K6) -> 20125.7 | M6: =M4*M24 -> 22210.106 | N6: =N4*N24 -> 18132.955
A7: Other Income | B7: ='Data Sheet'!B25 -> 1464.1 | C7: ='Data Sheet'!C25 -> 2399.2 | D7: ='Data Sheet'!D25 -> 2154.6 | E7: ='Data Sheet'!E25 -> 2664.2 | F7: ='Data Sheet'!F25 -> 3410.4 | G7: ='Data Sheet'!G25 -> 3046.3 | H7: ='Data Sheet'!H25 -> 1860.8 | I7: ='Data Sheet'!I25 -> 2306.6 | ... K7: ='Data Sheet'!K25 -> 5198.8 | L7: =SUM(Quarters!H7:K7) -> 5660.8 | M7: 0 | N7: 0
A8: Depreciation | B8: ='Data Sheet'!B26 -> 2821.8 | C8: ='Data Sheet'!C26 -> 2603.9 | D8: ='Data Sheet'!D26 -> 2759.8 | E8: ='Data Sheet'!E26 -> 3020.8 | F8: ='Data Sheet'!F26 -> 3528.4 | G8: ='Data Sheet'!G26 -> 3034.1 | H8: ='Data Sheet'!H26 -> 2789 | I8: ='Data Sheet'!I26 -> 2825.7 | ... K8: ='Data Sheet'!K26 -> 5608.2 | L8: =SUM(Quarters!H8:K8) -> 6455.4 | M8: =+$L8 -> 6455.4 | N8: =+$L8 -> 6455.4
A9: Interest | B9: ='Data Sheet'!B27 -> 81.7 | C9: ='Data Sheet'!C27 -> 89.4 | D9: ='Data Sheet'!D27 -> 345.8 | E9: ='Data Sheet'!E27 -> 75.9 | F9: ='Data Sheet'!F27 -> 134.2 | G9: ='Data Sheet'!G27 -> 101.8 | H9: ='Data Sheet'!H27 -> 126.6 | I9: ='Data Sheet'!I27 -> 187 | ... K9: ='Data Sheet'!K27 -> 194.2 | L9: =SUM(Quarters!H9:K9) -> 213.3 | M9: =+$L9 -> 213.3 | N9: =+$L9 -> 213.3
A10: Profit before tax | B10: ='Data Sheet'!B28 -> 7584.7 | C10: ='Data Sheet'!C28 -> 10127.2 | D10: ='Data Sheet'!D28 -> 11166.9 | E10: ='Data Sheet'!E28 -> 10623.8 | F10: ='Data Sheet'!F28 -> 7102.8 | G10: ='Data Sheet'!G28 -> 5321 | H10: ='Data Sheet'!H28 -> 4697.2 | I10: ='Data Sheet'!I28 -> 10323.1 | ... K10: ='Data Sheet'!K28 -> 19620 | L10: =SUM(Quarters!H10:K10) -> 19117.8 | M10: =M6+M7-SUM(M8:M9) -> 15541.406 | N10: =N6+N7-SUM(N8:N9) -> 11464.255
A11: Tax | B11: ='Data Sheet'!B29 -> 2087.5 | C11: ='Data Sheet'!C29 -> 2616.2 | D11: ='Data Sheet'!D29 -> 3286.2 | E11: ='Data Sheet'!E29 -> 2973.2 | F11: ='Data Sheet'!F29 -> 1425.2 | G11: ='Data Sheet'!G29 -> 931.9 | H11: ='Data Sheet'!H29 -> 817.7 | I11: ='Data Sheet'!I29 -> 2112.1 | ... K11: ='Data Sheet'!K29 -> 5119.8 | L11: =SUM(Quarters!H11:K11) -> 4186.2 | M11: =IF($L10>0,$L11/$L10,0) -> 0.21896871 | N11: =IF($L10>0,$L11/$L10,0) -> 0.21896871
A12: Net profit | B12: ='Data Sheet'!B30 -> 5497.2 | C12: ='Data Sheet'!C30 -> 7509.9 | D12: ='Data Sheet'!D30 -> 7880 | E12: ='Data Sheet'!E30 -> 7649.1 | F12: ='Data Sheet'!F30 -> 5676 | G12: ='Data Sheet'!G30 -> 4389.1 | H12: ='Data Sheet'!H30 -> 3879.5 | I12: ='Data Sheet'!I30 -> 8211 | ... K12: ='Data Sheet'!K30 -> 14500.2 | L12: =SUM(Quarters!H12:K12) -> 14931.6 | M12: =M10-M11*M10 -> 12138.325 | N12: =N10-N11*N10 -> 8953.9422
A13: EPS | B13: =IF('Data Sheet'!B93>0,B12/'Data Sheet'!B93,0) -> 181.96624 | C13: =IF('Data Sheet'!C93>0,C12/'Data Sheet'!C93,0) -> 248.58987 | D13: =IF('Data Sheet'!D93>0,D12/'Data Sheet'!D93,0) -> 260.84078 | E13: =IF('Data Sheet'!E93>0,E12/'Data Sheet'!E93,0) -> 253.19762 | F13: =IF('Data Sheet'!F93>0,F12/'Data Sheet'!F93,0) -> 187.88481 | G13: =IF('Data Sheet'!G93>0,G12/'Data Sheet'!G93,0) -> 145.28633 | H13: =IF('Data Sheet'!H93>0,H12/'Data Sheet'!H93,0) -> 128.41774 | I13: =IF('Data Sheet'!I93>0,I12/'Data Sheet'!I93,0) -> 271.79742 | ... K13: =IF('Data Sheet'!K93>0,K12/'Data Sheet'!K93,0) -> 461.20229 | L13: =IF('Data Sheet'!$B6>0,'Profit & Loss'!L12/'Data Sheet'!$B6,0) -> 474.91978 | M13: =IF('Data Sheet'!$B6>0,'Profit & Loss'!M12/'Data Sheet'!$B6,0) -> 386.07587 | N13: =IF('Data Sheet'!$B6>0,'Profit & Loss'!N12/'Data Sheet'!$B6,0) -> 284.79227
A14: Price to earning | B14: =IF(B15>0,B15/B13,"") -> 20.42302 | C14: =IF(C15>0,C15/C13,"") -> 24.199297 | D14: =IF(D15>0,D15/D13,"") -> 33.971298 | E14: =IF(E15>0,E15/E13,"") -> 26.353131 | F14: =IF(F15>0,F15/F13,"") -> 22.824091 | G14: =IF(G15>0,G15/G13,"") -> 47.2116 | H14: =IF(H15>0,H15/H13,"") -> 58.880493 | I14: =IF(I15>0,I15/I13,"") -> 30.508568 | ... K14: =IF(K15>0,K15/K13,"") -> 24.982855 | L14: =IF(L13>0,L15/L13,0) -> 26.596071 | M14: =M25 -> 27.864495 | N14: =N25 -> 26.596071
A15: Price | B15: ='Data Sheet'!B90 -> 3716.3 | C15: ='Data Sheet'!C90 -> 6015.7 | D15: ='Data Sheet'!D90 -> 8861.1 | E15: ='Data Sheet'!E90 -> 6672.55 | F15: ='Data Sheet'!F90 -> 4288.3 | G15: ='Data Sheet'!G90 -> 6859.2 | H15: ='Data Sheet'!H90 -> 7561.3 | I15: ='Data Sheet'!I90 -> 8292.15 | ... K15: ='Data Sheet'!K90 -> 11522.15 | L15: ='Data Sheet'!B8 -> 12631 | M15: =M13*M14 -> 10757.809 | N15: =N13*N14 -> 7574.3553
A17: RATIOS:
A18: Dividend Payout | B18: =IF('Data Sheet'!B30>0, 'Data Sheet'!B31/'Data Sheet'!B30, 0) -> 0.19227971 | C18: =IF('Data Sheet'!C30>0, 'Data Sheet'!C31/'Data Sheet'!C30, 0) -> 0.30160189 | D18: =IF('Data Sheet'!D30>0, 'Data Sheet'!D31/'Data Sheet'!D30, 0) -> 0.30659898 | E18: =IF('Data Sheet'!E30>0, 'Data Sheet'!E31/'Data Sheet'!E30, 0) -> 0.31585415 | F18: =IF('Data Sheet'!F30>0, 'Data Sheet'!F31/'Data Sheet'!F30, 0) -> 0.3192389 | G18: =IF('Data Sheet'!G30>0, 'Data Sheet'!G31/'Data Sheet'!G30, 0) -> 0.30963068 | H18: =IF('Data Sheet'!H30>0, 'Data Sheet'!H31/'Data Sheet'!H30, 0) -> 0.4670705 | I18: =IF('Data Sheet'!I30>0, 'Data Sheet'!I31/'Data Sheet'!I30, 0) -> 0.33101936 | ... K18: =IF('Data Sheet'!K30>0, 'Data Sheet'!K31/'Data Sheet'!K30, 0) -> 0.2927132
A19: OPM | B19: =IF(B6>0,B6/B4,0) -> 0.15669833 | C19: =IF(C6>0,C6/C4,0) -> 0.15306308 | D19: =IF(D6>0,D6/D4,0) -> 0.1518355 | E19: =IF(E6>0,E6/E4,0) -> 0.12845931 | F19: =IF(F6>0,F6/F4,0) -> 0.097211208 | G19: =IF(G6>0,G6/G4,0) -> 0.076885693 | H19: =IF(H6>0,H6/H4,0) -> 0.065119586 | I19: =IF(I6>0,I6/I4,0) -> 0.093808608 | ... L19: =IF(L6>0,L6/L4,0) -> 0.1171641
G22: TRENDS: | H22: 10 YEARS | I22: 7 YEARS | J22: 5 YEARS | K22: 3 YEARS | L22: RECENT | M22: BEST | N22: WORST
G23: Sales Growth | H23: =IF(B4=0,"",POWER($K4/B4,1/9)-1) -> 0.11460956 | I23: =IF(D4=0,"",POWER($K4/D4,1/7)-1) -> 0.097340683 | J23: =IF(F4=0,"",POWER($K4/F4,1/5)-1) -> 0.15110679 | K23: =IF(H4=0,"",POWER($K4/H4, 1/3)-1) -> 0.20073099 | L23: =IF(ISERROR(MAX(IF(J4=0,"",(K4-J4)/J4),IF(K4=0,"",(L4-K4)/K4))),"",MAX(IF(J4=0,"",(K4-J4)/J4),IF(K4=0,"",(L4-K4)/K4))) -> 0.12334203 | M23: =MAX(K23:L23) -> 0.20073099 | N23: =MIN(H23:L23) -> 0.097340683
G24: OPM | H24: =IF(SUM(B4:$K$4)=0,"",SUMPRODUCT(B19:$K$19,B4:$K$4)/SUM(B4:$K$4)) -> 0.11832195 | I24: =IF(SUM(E4:$K$4)=0,"",SUMPRODUCT(E19:$K$19,E4:$K$4)/SUM(E4:$K$4)) -> 0.10842788 | J24: =IF(SUM(G4:$K$4)=0,"",SUMPRODUCT(G19:$K$19,G4:$K$4)/SUM(G4:$K$4)) -> 0.10689486 | K24: =IF(SUM(I4:$K$4)=0, "", SUMPRODUCT(I19:$K$19,I4:$K$4)/SUM(I4:$K$4)) -> 0.12096522 | L24: =L19 -> 0.1171641 | M24: =MAX(K24:L24) -> 0.12096522 | N24: =MIN(H24:L24) -> 0.10689486
G25: Price to Earning | H25: =IF(ISERROR(AVERAGEIF(B14:$L14,">0")),"",AVERAGEIF(B14:$L14,">0")) -> 31.39281 | I25: =IF(ISERROR(AVERAGEIF(E14:$L14,">0")),"",AVERAGEIF(E14:$L14,">0")) -> 33.340912 | J25: =IF(ISERROR(AVERAGEIF(G14:$L14,">0")),"",AVERAGEIF(G14:$L14,">0")) -> 36.258346 | K25: =IF(ISERROR(AVERAGEIF(I14:$L14,">0")),"",AVERAGEIF(I14:$L14,">0")) -> 27.864495 | L25: =L14 -> 26.596071 | M25: =MAX(K25:L25) -> 27.864495 | N25: =MIN(H25:L25) -> 26.596071
A28: Sales Growth (y-o-y) | C28: =C4/B4-1 -> 0.18225703 | D28: =D4/C4-1 -> 0.17220239 | E28: =E4/D4-1 -> 0.078425599 | F28: =F4/E4-1 -> -0.12093275 | G28: =G4/F4-1 -> -0.06989162 | H28: =H4/G4-1 -> 0.25518388 | I28: =I4/H4-1 -> 0.33104909 | J28: =J4/I4-1 -> 0.20657167 | K28: =K4/J4-1 -> 0.077928523
A29: Gross Profit | B29: ='Data Sheet'!B17-SUM('Data Sheet'!B18:B21) -> 17770.7 | C29: ='Data Sheet'!C17-SUM('Data Sheet'!C18:C21) -> 19682.7 | D29: ='Data Sheet'!D17-SUM('Data Sheet'!D18:D21) -> 23769.4 | E29: ='Data Sheet'!E17-SUM('Data Sheet'!E18:E21) -> 25594.5 | F29: ='Data Sheet'!F17-SUM('Data Sheet'!F18:F21) -> 20941.7 | G29: ='Data Sheet'!G17-SUM('Data Sheet'!G18:G21) -> 18935.2 | H29: ='Data Sheet'!H17-SUM('Data Sheet'!H18:H21) -> 20616.2 | I29: ='Data Sheet'!I17-SUM('Data Sheet'!I18:I21) -> 28602 | ... K29: ='Data Sheet'!K17-SUM('Data Sheet'!K18:K21) -> 39920.2
A30: Gross Profit Margin | B30: =B29/B4 -> 0.30857803 | C30: =C29/C4 -> 0.28909011 | D30: =D29/D4 -> 0.29782707 | E30: =E29/E4 -> 0.2973736 | F30: =F29/F4 -> 0.27678694 | G30: =G29/G4 -> 0.26907293 | H30: =H29/H4 -> 0.23340028 | I30: =I29/I4 -> 0.24327366 | ... K30: =K29/K4 -> 0.26106479
A31: EBITDA Margins | B31: =B6/B4 -> 0.15669833 | C31: =C6/C4 -> 0.15306308 | D31: =D6/D4 -> 0.1518355 | E31: =E6/E4 -> 0.12845931 | F31: =F6/F4 -> 0.097211208 | G31: =G6/G4 -> 0.076885693 | H31: =H6/H4 -> 0.065119586 | I31: =I6/I4 -> 0.093808608 | ... K31: =K6/K4 -> 0.1322556
A32: EBIT Margins | B32: =(B6-B8)/B4 -> 0.10769939 | C32: =(C6-C8)/C4 -> 0.11481824 | D32: =(D6-D8)/D4 -> 0.11725561 | E32: =(E6-E8)/E4 -> 0.093361683 | F32: =(F6-F8)/F4 -> 0.050576262 | G32: =(G6-G8)/G4 -> 0.033770534 | H32: =(H6-H8)/H4 -> 0.033544738 | I32: =(I6-I8)/I4 -> 0.069774681 | ... K32: =(K6-K8)/K4 -> 0.09557984
A33: Net Profit Margins | B33: =B12/B4 -> 0.095455729 | C33: =C12/C4 -> 0.11030183 | D33: =D12/D4 -> 0.098735237 | E33: =E12/E4 -> 0.088872235 | F33: =F12/F4 -> 0.075019826 | G33: =G12/G4 -> 0.062369977 | H33: =H12/H4 -> 0.043920625 | I33: =I12/I4 -> 0.069838472 | ... K33: =K12/K4 -> 0.09482647
A34: EPS Growth | C34: =C13/B13-1 -> 0.36613185 | D34: =D13/C13-1 -> 0.049281615 | E34: =E13/D13-1 -> -0.02930203 | F34: =F13/E13-1 -> -0.25795192 | G34: =G13/F13-1 -> -0.22672657 | H34: =H13/G13-1 -> -0.11610581 | I34: =I13/H13-1 -> 1.1165099 | J34: =J13/I13-1 -> 0.57843293 | K34: =K13/J13-1 -> 0.075028543
A35: Dividend Per Share | B35: =B13*B18 -> 34.988414 | C35: =C13*C18 -> 74.975174 | D35: =D13*D18 -> 79.973519 | E35: =E13*E18 -> 79.973519 | F35: =F13*F18 -> 59.980139 | G35: =G13*G18 -> 44.985104 | H35: =H13*H18 -> 59.980139 | I35: =I13*I18 -> 89.970209 | ... K35: =K13*K18 -> 135
A36: Dividend Growth | C36: =C35/B35-1 -> 1.1428571 | D36: =D35/C35-1 -> 0.066666667 | E36: =E35/D35-1 -> 0 | F36: =F35/E35-1 -> -0.25 | G36: =G35/F35-1 -> -0.25 | H36: =H35/G35-1 -> 0.33333333 | I36: =I35/H35-1 -> 0.5 | J36: =J35/I35-1 -> 0.38934879 | K36: =K35/J35-1 -> 0.08
A38: market capitalization | B38: ='Data Sheet'!B93*'Data Sheet'!B90 -> 112269.42 | C38: ='Data Sheet'!C93*'Data Sheet'!C90 -> 181734.3 | D38: ='Data Sheet'!D93*'Data Sheet'!D90 -> 267693.83 | E38: ='Data Sheet'!E93*'Data Sheet'!E90 -> 201577.74 | F38: ='Data Sheet'!F93*'Data Sheet'!F90 -> 129549.54 | G38: ='Data Sheet'!G93*'Data Sheet'!G90 -> 207216.43 | H38: ='Data Sheet'!H93*'Data Sheet'!H90 -> 228426.87 | I38: ='Data Sheet'!I93*'Data Sheet'!I90 -> 250505.85 | ... K38: ='Data Sheet'!K93*'Data Sheet'!K90 -> 362256.4
A39: Debt | B39: ='Balance Sheet'!B6 -> 230.9 | C39: ='Balance Sheet'!C6 -> 483.6 | D39: ='Balance Sheet'!D6 -> 120.8 | E39: ='Balance Sheet'!E6 -> 159.6 | F39: ='Balance Sheet'!F6 -> 184.1 | G39: ='Balance Sheet'!G6 -> 540.9 | H39: ='Balance Sheet'!H6 -> 425.5 | I39: ='Balance Sheet'!I6 -> 1247.3 | ... K39: ='Balance Sheet'!K6 -> 87
A40: cash | B40: ='Data Sheet'!B69 -> 50.7 | C40: ='Data Sheet'!C69 -> 23.5 | D40: ='Data Sheet'!D69 -> 74 | E40: ='Data Sheet'!E69 -> 187.8 | F40: ='Data Sheet'!F69 -> 29 | G40: ='Data Sheet'!G69 -> 3047.1 | H40: ='Data Sheet'!H69 -> 3042.2 | I40: ='Data Sheet'!I69 -> 41.6 | ... K40: ='Data Sheet'!K69 -> 552.9
A41: EV | B41: =B38+B39-B40 -> 112449.62 | C41: =C38+C39-C40 -> 182194.4 | D41: =D38+D39-D40 -> 267740.63 | E41: =E38+E39-E40 -> 201549.54 | F41: =F38+F39-F40 -> 129704.64 | G41: =G38+G39-G40 -> 204710.23 | H41: =H38+H39-H40 -> 225810.17 | I41: =I38+I39-I40 -> 251711.55 | ... K41: =K38+K39-K40 -> 361790.5
A42: EV/EBITDA | B42: =B41/B6 -> 12.461035 | C42: =C41/C6 -> 17.482886 | D42: =D41/D6 -> 22.094639 | E42: =E41/E6 -> 18.229384 | F42: =F41/F6 -> 17.634894 | G42: =G41/G6 -> 37.835033 | H42: =H41/H6 -> 39.25768 | I42: =I41/I6 -> 22.822286 | ... K42: =K41/K6 -> 17.88952
A43: EV/Sales | B43: =B41/B4 -> 1.9526233 | C43: =C41/C4 -> 2.6759844 | D43: =D41/D4 -> 3.3547506 | E43: =E41/E4 -> 2.341734 | F43: =F41/F4 -> 1.7143093 | G43: =G41/G4 -> 2.9089728 | H43: =H41/H4 -> 2.5564438 | I43: =I41/I4 -> 2.1409268 | ... K43: =K41/K4 -> 2.3659891
A44: p/b | B44: =B38/'Balance Sheet'!B27 -> 3.667018 | C44: =C38/'Balance Sheet'!C27 -> 4.9017885 | D44: =D38/'Balance Sheet'!D27 -> 6.2898873 | E44: =E38/'Balance Sheet'!E27 -> 4.2805 | F44: =F38/'Balance Sheet'!F27 -> 2.6217704 | G44: =G38/'Balance Sheet'!G27 -> 3.9469345 | H44: =H38/'Balance Sheet'!H27 -> 4.1281841 | I44: =I38/'Balance Sheet'!I27 -> 4.0540635 | ... K44: =K38/'Balance Sheet'!K27 -> 3.7640978

Sheet Quarters
A1: ='Profit & Loss'!A1 -> MARUTI SUZUKI INDIA LTD | E1: =UPDATE | J1: SCREENER.IN
A3: Narration | B3: ='Data Sheet'!B41 -> 45199 | C3: ='Data Sheet'!C41 -> 45291 | D3: ='Data Sheet'!D41 -> 45382 | E3: ='Data Sheet'!E41 -> 45473 | F3: ='Data Sheet'!F41 -> 45565 | G3: ='Data Sheet'!G41 -> 45657 | H3: ='Data Sheet'!H41 -> 45747 | I3: ='Data Sheet'!I41 -> 45838 | ... K3: ='Data Sheet'!K41 -> 46022
A4: Sales | B4: ='Data Sheet'!B42 -> 37339.4 | C4: ='Data Sheet'!C42 -> 33512.8 | D4: ='Data Sheet'!D42 -> 38471.2 | E4: ='Data Sheet'!E42 -> 35779.4 | F4: ='Data Sheet'!F42 -> 37449.2 | G4: ='Data Sheet'!G42 -> 38764.3 | H4: ='Data Sheet'!H42 -> 40920.1 | I4: ='Data Sheet'!I42 -> 38605.2 | ... K4: ='Data Sheet'!K42 -> 49904.1
A5: Expenses | B5: ='Data Sheet'!B43 -> 32027.9 | C5: ='Data Sheet'!C43 -> 29072.8 | D5: ='Data Sheet'!D43 -> 33250.1 | E5: ='Data Sheet'!E43 -> 30672.8 | F5: ='Data Sheet'!F43 -> 32450.4 | G5: ='Data Sheet'!G43 -> 33687.8 | H5: ='Data Sheet'!H43 -> 36076.1 | I5: ='Data Sheet'!I43 -> 33982.6 | ... K5: ='Data Sheet'!K43 -> 44331
A6: Operating Profit | B6: ='Data Sheet'!B50 -> 5311.5 | C6: ='Data Sheet'!C50 -> 4440 | D6: ='Data Sheet'!D50 -> 5221.1 | E6: ='Data Sheet'!E50 -> 5106.6 | F6: ='Data Sheet'!F50 -> 4998.8 | G6: ='Data Sheet'!G50 -> 5076.5 | H6: ='Data Sheet'!H50 -> 4844 | I6: ='Data Sheet'!I50 -> 4622.6 | ... K6: ='Data Sheet'!K50 -> 5573.1
A7: Other Income | B7: ='Data Sheet'!B44 -> 957.8 | C7: ='Data Sheet'!C44 -> 1052.9 | D7: ='Data Sheet'!D44 -> 1261 | E7: ='Data Sheet'!E44 -> 1118.1 | F7: ='Data Sheet'!F44 -> 1570.5 | G7: ='Data Sheet'!G44 -> 1124.8 | H7: ='Data Sheet'!H44 -> 1583.1 | I7: ='Data Sheet'!I44 -> 1923.7 | ... K7: ='Data Sheet'!K44 -> 1140.5
A8: Depreciation | B8: ='Data Sheet'!B45 -> 1341.9 | C8: ='Data Sheet'!C45 -> 1301.5 | D8: ='Data Sheet'!D45 -> 1298.3 | E8: ='Data Sheet'!E45 -> 1331.7 | F8: ='Data Sheet'!F45 -> 1385.7 | G8: ='Data Sheet'!G45 -> 1429 | H8: ='Data Sheet'!H45 -> 1461.8 | I8: ='Data Sheet'!I45 -> 1556 | ... K8: ='Data Sheet'!K45 -> 1734.6
A9: Interest | B9: ='Data Sheet'!B46 -> 35.1 | C9: ='Data Sheet'!C46 -> 35.8 | D9: ='Data Sheet'!D46 -> 76.2 | E9: ='Data Sheet'!E46 -> 57.3 | F9: ='Data Sheet'!F46 -> 43 | G9: ='Data Sheet'!G46 -> 46.3 | H9: ='Data Sheet'!H46 -> 47.6 | I9: ='Data Sheet'!I46 -> 46.8 | ... K9: ='Data Sheet'!K46 -> 61.7
A10: Profit before tax | B10: ='Data Sheet'!B47 -> 4892.3 | C10: ='Data Sheet'!C47 -> 4155.6 | D10: ='Data Sheet'!D47 -> 5107.6 | E10: ='Data Sheet'!E47 -> 4835.7 | F10: ='Data Sheet'!F47 -> 5140.6 | G10: ='Data Sheet'!G47 -> 4726 | H10: ='Data Sheet'!H47 -> 4917.7 | I10: ='Data Sheet'!I47 -> 4943.5 | ... K10: ='Data Sheet'!K47 -> 4917.3
A11: Tax | B11: ='Data Sheet'!B48 -> 1106.1 | C11: ='Data Sheet'!C48 -> 948.8 | D11: ='Data Sheet'!D48 -> 1155.3 | E11: ='Data Sheet'!E48 -> 1076 | F11: ='Data Sheet'!F48 -> 2038.1 | G11: ='Data Sheet'!G48 -> 999.1 | H11: ='Data Sheet'!H48 -> 1006.6 | I11: ='Data Sheet'!I48 -> 1151.1 | ... K11: ='Data Sheet'!K48 -> 1038.2
A12: Net profit | B12: ='Data Sheet'!B49 -> 3786.2 | C12: ='Data Sheet'!C49 -> 3206.8 | D12: ='Data Sheet'!D49 -> 3952.3 | E12: ='Data Sheet'!E49 -> 3759.7 | F12: ='Data Sheet'!F49 -> 3102.5 | G12: ='Data Sheet'!G49 -> 3726.9 | H12: ='Data Sheet'!H49 -> 3911.1 | I12: ='Data Sheet'!I49 -> 3792.4 | ... K12: ='Data Sheet'!K49 -> 3879.1
A14: OPM | B14: =IF(B4>0,B6/B4,"") -> 0.14224921 | C14: =IF(C4>0,C6/C4,"") -> 0.13248669 | D14: =IF(D4>0,D6/D4,"") -> 0.13571451 | E14: =IF(E4>0,E6/E4,"") -> 0.14272458 | F14: =IF(F4>0,F6/F4,"") -> 0.13348216 | G14: =IF(G4>0,G6/G4,"") -> 0.13095812 | H14: =IF(H4>0,H6/H4,"") -> 0.11837703 | I14: =IF(I4>0,I6/I4,"") -> 0.11974035 | ... K14: =IF(K4>0,K6/K4,"") -> 0.11167619

Sheet Balance Sheet
A1: ='Profit & Loss'!A1 -> MARUTI SUZUKI INDIA LTD | E1: =UPDATE | J1: SCREENER.IN
A3: Narration | B3: ='Data Sheet'!B56 -> 42460 | C3: ='Data Sheet'!C56 -> 42825 | D3: ='Data Sheet'!D56 -> 43190 | E3: ='Data Sheet'!E56 -> 43555 | F3: ='Data Sheet'!F56 -> 43921 | G3: ='Data Sheet'!G56 -> 44286 | H3: ='Data Sheet'!H56 -> 44651 | I3: ='Data Sheet'!I56 -> 45016 | ... K3: ='Data Sheet'!K56 -> 45747
A4: Equity Share Capital | B4: ='Data Sheet'!B57 -> 151 | C4: ='Data Sheet'!C57 -> 151 | D4: ='Data Sheet'!D57 -> 151 | E4: ='Data Sheet'!E57 -> 151 | F4: ='Data Sheet'!F57 -> 151 | G4: ='Data Sheet'!G57 -> 151 | H4: ='Data Sheet'!H57 -> 151 | I4: ='Data Sheet'!I57 -> 151 | ... K4: ='Data Sheet'!K57 -> 157.2
A5: Reserves | B5: ='Data Sheet'!B58 -> 30465 | C5: ='Data Sheet'!C58 -> 36924.1 | D5: ='Data Sheet'!D58 -> 42408.4 | E5: ='Data Sheet'!E58 -> 46941.1 | F5: ='Data Sheet'!F58 -> 49262 | G5: ='Data Sheet'!G58 -> 52349.6 | H5: ='Data Sheet'!H58 -> 55182.5 | I5: ='Data Sheet'!I58 -> 61640.3 | ... K5: ='Data Sheet'!K58 -> 96082.7
A6: Borrowings | B6: ='Data Sheet'!B59 -> 230.9 | C6: ='Data Sheet'!C59 -> 483.6 | D6: ='Data Sheet'!D59 -> 120.8 | E6: ='Data Sheet'!E59 -> 159.6 | F6: ='Data Sheet'!F59 -> 184.1 | G6: ='Data Sheet'!G59 -> 540.9 | H6: ='Data Sheet'!H59 -> 425.5 | I6: ='Data Sheet'!I59 -> 1247.3 | ... K6: ='Data Sheet'!K59 -> 87
A7: Other Liabilities | B7: ='Data Sheet'!B60 -> 11878.6 | C7: ='Data Sheet'!C60 -> 14401.8 | D7: ='Data Sheet'!D60 -> 17568.2 | E7: ='Data Sheet'!E60 -> 16717 | F7: ='Data Sheet'!F60 -> 14030.6 | G7: ='Data Sheet'!G60 -> 18334.6 | H7: ='Data Sheet'!H60 -> 18896.5 | I7: ='Data Sheet'!I60 -> 21558.3 | ... K7: ='Data Sheet'!K60 -> 35644.3
A8: Total | B8: ='Data Sheet'!B61 -> 42725.5 | C8: ='Data Sheet'!C61 -> 51960.5 | D8: ='Data Sheet'!D61 -> 60248.4 | E8: ='Data Sheet'!E61 -> 63968.7 | F8: ='Data Sheet'!F61 -> 63627.7 | G8: ='Data Sheet'!G61 -> 71376.1 | H8: ='Data Sheet'!H61 -> 74655.5 | I8: ='Data Sheet'!I61 -> 84596.9 | ... K8: ='Data Sheet'!K61 -> 131971.2
A10: Net Block | B10: ='Data Sheet'!B62 -> 12529.6 | C10: ='Data Sheet'!C62 -> 13310.7 | D10: ='Data Sheet'!D62 -> 13388.8 | E10: ='Data Sheet'!E62 -> 15437.3 | F10: ='Data Sheet'!F62 -> 15744.4 | G10: ='Data Sheet'!G62 -> 14988.7 | H10: ='Data Sheet'!H62 -> 13747.2 | I10: ='Data Sheet'!I62 -> 17830.4 | ... K10: ='Data Sheet'!K62 -> 32982.7
A11: Capital Work in Progress | B11: ='Data Sheet'!B63 -> 1006.9 | C11: ='Data Sheet'!C63 -> 1252.3 | D11: ='Data Sheet'!D63 -> 2132.1 | E11: ='Data Sheet'!E63 -> 1606.9 | F11: ='Data Sheet'!F63 -> 1415.2 | G11: ='Data Sheet'!G63 -> 1496.8 | H11: ='Data Sheet'!H63 -> 2936.5 | I11: ='Data Sheet'!I63 -> 2904.1 | ... K11: ='Data Sheet'!K63 -> 7929
A12: Investments | B12: ='Data Sheet'!B64 -> 20675.8 | C12: ='Data Sheet'!C64 -> 29150.6 | D12: ='Data Sheet'!D64 -> 36123.1 | E12: ='Data Sheet'!E64 -> 37503.6 | F12: ='Data Sheet'!F64 -> 37488 | G12: ='Data Sheet'!G64 -> 42944.8 | H12: ='Data Sheet'!H64 -> 42034.7 | I12: ='Data Sheet'!I64 -> 49184.3 | ... K12: ='Data Sheet'!K64 -> 66265.4
A13: Other Assets | B13: ='Data Sheet'!B65 -> 8513.2 | C13: ='Data Sheet'!C65 -> 8246.9 | D13: ='Data Sheet'!D65 -> 8604.4 | E13: ='Data Sheet'!E65 -> 9420.9 | F13: ='Data Sheet'!F65 -> 8980.1 | G13: ='Data Sheet'!G65 -> 11945.8 | H13: ='Data Sheet'!H65 -> 15937.1 | I13: ='Data Sheet'!I65 -> 14678.1 | ... K13: ='Data Sheet'!K65 -> 24794.1
A14: Total | B14: ='Data Sheet'!B66 -> 42725.5 | C14: ='Data Sheet'!C66 -> 51960.5 | D14: ='Data Sheet'!D66 -> 60248.4 | E14: ='Data Sheet'!E66 -> 63968.7 | F14: ='Data Sheet'!F66 -> 63627.7 | G14: ='Data Sheet'!G66 -> 71376.1 | H14: ='Data Sheet'!H66 -> 74655.5 | I14: ='Data Sheet'!I66 -> 84596.9 | ... K14: ='Data Sheet'!K66 -> 131971.2
A16: Working Capital | B16: =B13-B7 -> -3365.4 | C16: =C13-C7 -> -6154.9 | D16: =D13-D7 -> -8963.8 | E16: =E13-E7 -> -7296.1 | F16: =F13-F7 -> -5050.5 | G16: =G13-G7 -> -6388.8 | H16: =H13-H7 -> -2959.4 | I16: =I13-I7 -> -6880.2 | ... K16: =K13-K7 -> -10850.2
A17: Debtors | B17: ='Data Sheet'!B67 -> 1323.4 | C17: ='Data Sheet'!C67 -> 1202.6 | D17: ='Data Sheet'!D67 -> 1465.4 | E17: ='Data Sheet'!E67 -> 2312.8 | F17: ='Data Sheet'!F67 -> 1977.7 | G17: ='Data Sheet'!G67 -> 1279.9 | H17: ='Data Sheet'!H67 -> 2034.5 | I17: ='Data Sheet'!I67 -> 3301.4 | ... K17: ='Data Sheet'!K67 -> 6539.7
A18: Inventory | B18: ='Data Sheet'!B68 -> 3132.6 | C18: ='Data Sheet'!C68 -> 3263.7 | D18: ='Data Sheet'!D68 -> 3160.2 | E18: ='Data Sheet'!E68 -> 3322.6 | F18: ='Data Sheet'!F68 -> 3213.9 | G18: ='Data Sheet'!G68 -> 3049 | H18: ='Data Sheet'!H68 -> 3532.3 | I18: ='Data Sheet'!I68 -> 4283.5 | ... K18: ='Data Sheet'!K68 -> 6913.2
A20: Debtor Days | B20: =IF('Profit & Loss'!B4>0,'Balance Sheet'!B17/('Profit & Loss'!B4/365),0) -> 8.3877303 | C20: =IF('Profit & Loss'!C4>0,'Balance Sheet'!C17/('Profit & Loss'!C4/365),0) -> 6.4470735 | D20: =IF('Profit & Loss'!D4>0,'Balance Sheet'!D17/('Profit & Loss'!D4/365),0) -> 6.7018547 | E20: =IF('Profit & Loss'!E4>0,'Balance Sheet'!E17/('Profit & Loss'!E4/365),0) -> 9.8081412 | F20: =IF('Profit & Loss'!F4>0,'Balance Sheet'!F17/('Profit & Loss'!F4/365),0) -> 9.5408472 | G20: =IF('Profit & Loss'!G4>0,'Balance Sheet'!G17/('Profit & Loss'!G4/365),0) -> 6.6384855 | H20: =IF('Profit & Loss'!H4>0,'Balance Sheet'!H17/('Profit & Loss'!H4/365),0) -> 8.4070438 | I20: =IF('Profit & Loss'!I4>0,'Balance Sheet'!I17/('Profit & Loss'!I4/365),0) -> 10.249193 | ... K20: =IF('Profit & Loss'!K4>0,'Balance Sheet'!K17/('Profit & Loss'!K4/365),0) -> 15.610121
A21: Inventory Turnover | B21: =IF('Balance Sheet'!B18>0,'Profit & Loss'!B4/'Balance Sheet'!B18,0) -> 18.383771 | C21: =IF('Balance Sheet'!C18>0,'Profit & Loss'!C4/'Balance Sheet'!C18,0) -> 20.861292 | D21: =IF('Balance Sheet'!D18>0,'Profit & Loss'!D4/'Balance Sheet'!D18,0) -> 25.254541 | E21: =IF('Balance Sheet'!E18>0,'Profit & Loss'!E4/'Balance Sheet'!E18,0) -> 25.903961 | F21: =IF('Balance Sheet'!F18>0,'Profit & Loss'!F4/'Balance Sheet'!F18,0) -> 23.541492 | G21: =IF('Balance Sheet'!G18>0,'Profit & Loss'!G4/'Balance Sheet'!G18,0) -> 23.080354 | H21: =IF('Balance Sheet'!H18>0,'Profit & Loss'!H4/'Balance Sheet'!H18,0) -> 25.006313 | I21: =IF('Balance Sheet'!I18>0,'Profit & Loss'!I4/'Balance Sheet'!I18,0) -> 27.447485 | ... K21: =IF('Balance Sheet'!K18>0,'Profit & Loss'!K4/'Balance Sheet'!K18,0) -> 22.11899
A23: Return on Equity | B23: =IF(SUM('Balance Sheet'!B4:B5)>0,'Profit & Loss'!B12/SUM('Balance Sheet'!B4:B5),"") -> 0.17955317 | C23: =IF(SUM('Balance Sheet'!C4:C5)>0,'Profit & Loss'!C12/SUM('Balance Sheet'!C4:C5),"") -> 0.20255913 | D23: =IF(SUM('Balance Sheet'!D4:D5)>0,'Profit & Loss'!D12/SUM('Balance Sheet'!D4:D5),"") -> 0.18515299 | E23: =IF(SUM('Balance Sheet'!E4:E5)>0,'Profit & Loss'!E12/SUM('Balance Sheet'!E4:E5),"") -> 0.16242852 | F23: =IF(SUM('Balance Sheet'!F4:F5)>0,'Profit & Loss'!F12/SUM('Balance Sheet'!F4:F5),"") -> 0.11486856 | G23: =IF(SUM('Balance Sheet'!G4:G5)>0,'Profit & Loss'!G12/SUM('Balance Sheet'!G4:G5),"") -> 0.083600949 | H23: =IF(SUM('Balance Sheet'!H4:H5)>0,'Profit & Loss'!H12/SUM('Balance Sheet'!H4:H5),"") -> 0.070111235 | I23: =IF(SUM('Balance Sheet'!I4:I5)>0,'Profit & Loss'!I12/SUM('Balance Sheet'!I4:I5),"") -> 0.13288278 | ... K23: =IF(SUM('Balance Sheet'!K4:K5)>0,'Profit & Loss'!K12/SUM('Balance Sheet'!K4:K5),"") -> 0.15066724
A24: Return on Capital Emp | C24: =IF((B4+B5+B6+C4+C5+C6)>0,('Profit & Loss'!C10+'Profit & Loss'!C9)*2/(B4+B5+B6+C4+C5+C6),"") -> 0.29870654 | D24: =IF((C4+C5+C6+D4+D5+D6)>0,('Profit & Loss'!D10+'Profit & Loss'!D9)*2/(C4+C5+C6+D4+D5+D6),"") -> 0.28696056 | E24: =IF((D4+D5+D6+E4+E5+E6)>0,('Profit & Loss'!E10+'Profit & Loss'!E9)*2/(D4+D5+D6+E4+E5+E6),"") -> 0.23795116 | F24: =IF((E4+E5+E6+F4+F5+F6)>0,('Profit & Loss'!F10+'Profit & Loss'!F9)*2/(E4+E5+E6+F4+F5+F6),"") -> 0.14944945 | G24: =IF((F4+F5+F6+G4+G5+G6)>0,('Profit & Loss'!G10+'Profit & Loss'!G9)*2/(F4+F5+F6+G4+G5+G6),"") -> 0.10566785 | H24: =IF((G4+G5+G6+H4+H5+H6)>0,('Profit & Loss'!H10+'Profit & Loss'!H9)*2/(G4+G5+G6+H4+H5+H6),"") -> 0.088672387 | I24: =IF((H4+H5+H6+I4+I5+I6)>0,('Profit & Loss'!I10+'Profit & Loss'!I9)*2/(H4+H5+H6+I4+I5+I6),"") -> 0.17694129 | J24: =IF((I4+I5+I6+J4+J5+J6)>0,('Profit & Loss'!J10+'Profit & Loss'!J9)*2/(I4+I5+I6+J4+J5+J6),"") -> 0.23681324 | K24: =IF((J4+J5+J6+K4+K5+K6)>0,('Profit & Loss'!K10+'Profit & Loss'!K9)*2/(J4+J5+J6+K4+K5+K6),"") -> 0.217641
A27: Book value | B27: =B4+B5 -> 30616 | C27: =C4+C5 -> 37075.1 | D27: =D4+D5 -> 42559.4 | E27: =E4+E5 -> 47092.1 | F27: =F4+F5 -> 49413 | G27: =G4+G5 -> 52500.6 | H27: =H4+H5 -> 55333.5 | I27: =I4+I5 -> 61791.3 | ... K27: =K4+K5 -> 96239.9

Sheet Cash Flow
A1: ='Balance Sheet'!A1 -> MARUTI SUZUKI INDIA LTD | E1: =UPDATE | J1: SCREENER.IN
A3: Narration | B3: ='Data Sheet'!B81 -> 42460 | C3: ='Data Sheet'!C81 -> 42825 | D3: ='Data Sheet'!D81 -> 43190 | E3: ='Data Sheet'!E81 -> 43555 | F3: ='Data Sheet'!F81 -> 43921 | G3: ='Data Sheet'!G81 -> 44286 | H3: ='Data Sheet'!H81 -> 44651 | I3: ='Data Sheet'!I81 -> 45016 | ... K3: ='Data Sheet'!K81 -> 45747
A4: Cash from Operating Activity | B4: ='Data Sheet'!B82 -> 8482.5 | C4: ='Data Sheet'!C82 -> 10282 | D4: ='Data Sheet'!D82 -> 11787.9 | E4: ='Data Sheet'!E82 -> 6600.9 | F4: ='Data Sheet'!F82 -> 3495.8 | G4: ='Data Sheet'!G82 -> 8856.2 | H4: ='Data Sheet'!H82 -> 1840.5 | I4: ='Data Sheet'!I82 -> 9251.4 | ... K4: ='Data Sheet'!K82 -> 16136.2
A5: Cash from Investing Activity | B5: ='Data Sheet'!B83 -> -7230.4 | C5: ='Data Sheet'!C83 -> -9173.2 | D5: ='Data Sheet'!D83 -> -8301.7 | E5: ='Data Sheet'!E83 -> -3539.9 | F5: ='Data Sheet'!F83 -> -556.6 | G5: ='Data Sheet'!G83 -> -7291.3 | H5: ='Data Sheet'!H83 -> -239.2 | I5: ='Data Sheet'!I83 -> -8036.1 | ... K5: ='Data Sheet'!K83 -> -14456.1
A6: Cash from Financing Activity | B6: ='Data Sheet'!B84 -> -1236.6 | C6: ='Data Sheet'!C84 -> -1129.3 | D6: ='Data Sheet'!D84 -> -3436.1 | E6: ='Data Sheet'!E84 -> -2947.9 | F6: ='Data Sheet'!F84 -> -3104.3 | G6: ='Data Sheet'!G84 -> -1544.9 | H6: ='Data Sheet'!H84 -> -1607 | I6: ='Data Sheet'!I84 -> -1213.1 | ... K6: ='Data Sheet'!K84 -> -4155.1
A7: Net Cash Flow | B7: ='Data Sheet'!B85 -> 15.5 | C7: ='Data Sheet'!C85 -> -20.5 | D7: ='Data Sheet'!D85 -> 50.1 | E7: ='Data Sheet'!E85 -> 113.1 | F7: ='Data Sheet'!F85 -> -165.1 | G7: ='Data Sheet'!G85 -> 20 | H7: ='Data Sheet'!H85 -> -5.7 | I7: ='Data Sheet'!I85 -> 2.2 | ... K7: ='Data Sheet'!K85 -> -2475

Sheet Data Sheet
A1: COMPANY NAME | B1: MARUTI SUZUKI INDIA LTD | E1: =IF(B2<>B3, "A NEW VERSION OF THE WORKSHEET IS AVAILABLE", "")
A2: LATEST VERSION | B2: 2.1 | E2: PLEASE DO NOT MAKE ANY CHANGES TO THIS SHEET
A3: CURRENT VERSION | B3: 2.1
A5: META
A6: Number of shares | B6: =IF(B9>0, B9/B8, 0) -> 31.440257
A7: Face Value | B7: 5
A8: Current Price | B8: 12631
A9: Market Capitalization | B9: 397121.89
A15: PROFIT & LOSS
A16: Report Date | B16: 42460 | C16: 42825 | D16: 43190 | E16: 43555 | F16: 43921 | G16: 44286 | H16: 44651 | I16: 45016 | J16: 45382 | K16: 45747
A17: Sales | B17: 57589 | C17: 68085 | D17: 79809.4 | E17: 86068.5 | F17: 75660 | G17: 70372 | H17: 88329.8 | I17: 117571.3 | J17: 141858.2 | K17: 152913
A18: Raw Material Cost | B18: 38701.2 | C18: 47121.5 | D18: 54945.3 | E18: 59346.6 | F18: 53402 | G18: 50550.5 | H18: 66137.1 | I18: 86654.7 | J18: 100119.5 | K18: 108718.3
A19: Change in Inventory | B19: -4.8 | C19: 379.3 | D19: -40.8 | E19: -211.6 | F19: 238.7 | G19: -273.6 | H19: 93.1 | I19: 403.9 | J19: 378.6 | K19: 1227.5
A20: Power and Fuel | B20: 694.1 | C20: 518.6 | D20: 673.4 | E20: 863.3 | F20: 699.5 | G20: 476.6 | H20: 630.9 | I20: 790 | J20: 1033.4 | K20: 1052.6
A21: Other Mfr. Exp | B21: 427.8 | C21: 382.9 | D21: 462.1 | E21: 475.7 | F21: 378.1 | G21: 683.3 | H21: 852.5 | I21: 1120.7 | J21: 939.3 | K21: 1994.4
A22: Employee Cost | B22: 2000.3 | C22: 2360.3 | D22: 2863.4 | E22: 3285 | F22: 3416.2 | G22: 3431.6 | H22: 4051.4 | I22: 4634.6 | J22: 6301.6 | K22: 7026
A23: Selling and admin | B23: 5367.3 | C23: 6111.3 | D23: 6755.3 | E23: 8390.3 | F23: 8456.3 | G23: 7924 | H23: 9119.1 | I23: 11695 | J23: 12082.6 | K23: 11523.3
A24: Other Expenses | B24: 1369.4 | C24: 1548.4 | D24: 1951.2 | E24: 2439.7 | F24: 2191.6 | G24: 1621.8 | H24: 1879.9 | I24: 2051 | J24: 3134.1 | K24: 3602.3
A25: Other Income | B25: 1464.1 | C25: 2399.2 | D25: 2154.6 | E25: 2664.2 | F25: 3410.4 | G25: 3046.3 | H25: 1860.8 | I25: 2306.6 | J25: 4247.6 | K25: 5198.8
A26: Depreciation | B26: 2821.8 | C26: 2603.9 | D26: 2759.8 | E26: 3020.8 | F26: 3528.4 | G26: 3034.1 | H26: 2789 | I26: 2825.7 | J26: 5255.8 | K26: 5608.2
A27: Interest | B27: 81.7 | C27: 89.4 | D27: 345.8 | E27: 75.9 | F27: 134.2 | G27: 101.8 | H27: 126.6 | I27: 187 | J27: 193.6 | K27: 194.2
... A31: Dividend Amount | B31: 1057 | C31: 2265 | D31: 2416 | E31: 2416 | F31: 1812 | G31: 1359 | H31: 1812 | I31: 2718 | J31: 3930 | K31: 4244.4
A40: Quarters
A41: Report Date | B41: 45199 | C41: 45291 | D41: 45382 | E41: 45473 | F41: 45565 | G41: 45657 | H41: 45747 | I41: 45838 | J41: 45930 | K41: 46022
A42: Sales | B42: 37339.4 | C42: 33512.8 | D42: 38471.2 | E42: 35779.4 | F42: 37449.2 | G42: 38764.3 | H42: 40920.1 | I42: 38605.2 | J42: 42344.2 | K42: 49904.1
A43: Expenses | B43: 32027.9 | C43: 29072.8 | D43: 33250.1 | E43: 30672.8 | F43: 32450.4 | G43: 33687.8 | H43: 36076.1 | I43: 33982.6 | J43: 37258.2 | K43: 44331
A44: Other Income | B44: 957.8 | C44: 1052.9 | D44: 1261 | E44: 1118.1 | F44: 1570.5 | G44: 1124.8 | H44: 1583.1 | I44: 1923.7 | J44: 1013.5 | K44: 1140.5
A45: Depreciation | B45: 1341.9 | C45: 1301.5 | D45: 1298.3 | E45: 1331.7 | F45: 1385.7 | G45: 1429 | H45: 1461.8 | I45: 1556 | J45: 1703 | K45: 1734.6
A46: Interest | B46: 35.1 | C46: 35.8 | D46: 76.2 | E46: 57.3 | F46: 43 | G46: 46.3 | H46: 47.6 | I46: 46.8 | J46: 57.2 | K46: 61.7
A47: Profit before tax | B47: 4892.3 | C47: 4155.6 | D47: 5107.6 | E47: 4835.7 | F47: 5140.6 | G47: 4726 | H47: 4917.7 | I47: 4943.5 | J47: 4339.3 | K47: 4917.3
A48: Tax | B48: 1106.1 | C48: 948.8 | D48: 1155.3 | E48: 1076 | F48: 2038.1 | G48: 999.1 | H48: 1006.6 | I48: 1151.1 | J48: 990.3 | K48: 1038.2
A49: Net profit | B49: 3786.2 | C49: 3206.8 | D49: 3952.3 | E49: 3759.7 | F49: 3102.5 | G49: 3726.9 | H49: 3911.1 | I49: 3792.4 | J49: 3349 | K49: 3879.1
A50: Operating Profit | B50: 5311.5 | C50: 4440 | D50: 5221.1 | E50: 5106.6 | F50: 4998.8 | G50: 5076.5 | H50: 4844 | I50: 4622.6 | J50: 5086 | K50: 5573.1
A55: BALANCE SHEET
A56: Report Date | B56: 42460 | C56: 42825 | D56: 43190 | E56: 43555 | F56: 43921 | G56: 44286 | H56: 44651 | I56: 45016 | J56: 45382 | K56: 45747
A57: Equity Share Capital | B57: 151 | C57: 151 | D57: 151 | E57: 151 | F57: 151 | G57: 151 | H57: 151 | I57: 151 | J57: 157.2 | K57: 157.2
A58: Reserves | B58: 30465 | C58: 36924.1 | D58: 42408.4 | E58: 46941.1 | F58: 49262 | G58: 52349.6 | H58: 55182.5 | I58: 61640.3 | J58: 85478.8 | K58: 96082.7
A59: Borrowings | B59: 230.9 | C59: 483.6 | D59: 120.8 | E59: 159.6 | F59: 184.1 | G59: 540.9 | H59: 425.5 | I59: 1247.3 | J59: 118.6 | K59: 87
A60: Other Liabilities | B60: 11878.6 | C60: 14401.8 | D60: 17568.2 | E60: 16717 | F60: 14030.6 | G60: 18334.6 | H60: 18896.5 | I60: 21558.3 | J60: 29549.5 | K60: 35644.3
A61: Total | B61: 42725.5 | C61: 51960.5 | D61: 60248.4 | E61: 63968.7 | F61: 63627.7 | G61: 71376.1 | H61: 74655.5 | I61: 84596.9 | J61: 115304.1 | K61: 131971.2
...

Sheet Customization
A1: How to use it?
A3: You can customize this workbook as you want.
B4: You can add custom formating, add conditional formating, add your own formulas… do ANYTHING.
B5: Please don't edit the "Data Sheet" only.
A7: After customization, you can upload this back on Screener.
B8: Upload on: | C8: https://www.screener.in/excel/
A10: Download your customized workbooks now onwards.
B11: Now whenever you will "Export to excel" from Screener, it will export your customized file.
A14: TESTING:
B15: This is a testing feature currently.
B16: You can report any formula errors on the worksheet at: support@screener.in

Sheet Input
B6: Maruti Suzuki India Limited is the Indian subsidiary of Japanese automaker Suzuki Motor Corporation. It is the largest automobile manufacturer in India, specialising in small cars. The company was established by the Government of India as Maruti Udyog Limited in February 1981 as a joint venture with Suzuki, the latter becoming the first Japanese automaker, as well as the first major foreign automaker, to invest in India
AA7: 100
AB8: 100000
V9: 1 | W9: Shareholder's name | X9: N. Shares (in Crs) | Y9: (%) holding | Z9: Market Value (in Crs.)
C10: Date | D10: Adj Close | E10: Volume | G10: 10000 | V10: 1 | W10: Suzuki Motor Corporation | X10: 1832.4648 | Y10: 0.5828 | Z10: =12631*X10 -> 23145862
C11: 46114 | D11: 12632.25 | E11: 36989 | V11: 2 | W11: LICI ULIP-Growth Fund | X11: 135.17739 | Y11: 0.043 | Z11: =12631*X11 -> 1707425.6
C12: 46113 | D12: 12508.3 | E12: 27500 | V12: 3 | W12: ICICI N50 Equal Weight Index Fund | X12: 99.48721 | Y12: 0.0316 | Z12: =12631*X12 -> 1256622.9
C13: 46111 | D13: 12298.8 | E13: 19155 | V13: 4 | W13: SBI ESG Exclusionary Strategy Fund | X13: 72.03103 | Y13: 0.0229 | Z13: =12631*X13 -> 909823.94
C14: 46108 | D14: 12387.9 | E14: 22889 | V14: 5 | W14: HDFC Trustee Company Ltd-Flexi Fund | X14: 67.57821 | Y14: 0.0215 | Z14: =12631*X14 -> 853580.37
C15: 46106 | D15: 12704.3 | E15: 43366 | V15: 6 | W15: NPS UTI Pension Fund Ltd-Scheme Cent | X15: 43.68427 | Y15: 0.0139 | Z15: =12631*X15 -> 551776.01
C16: 46105 | D16: 12467.5 | E16: 60566 | V16: 7 | W16: Kotak Balanced Advantage Fund | X16: 38.74829 | Y16: 0.0123 | Z16: =12631*X16 -> 489429.65
C17: 46104 | D17: 12354.05 | E17: 33513 | V17: 8 | W17: UTI Manufacturing Index Fund | X17: 36.43827 | Y17: 0.0116 | Z17: =12631*X17 -> 460251.79
C18: 46100 | D18: 12591.45 | E18: 61601 | V18: 9 | W18: Nippon India Large Cap Fund | X18: 30.25 | Y18: 0.0096 | Z18: =12631*X18 -> 382087.75
C19: 46099 | D19: 13054.65 | E19: 121957 | V19: 10 | W19: Axis Bluechip Fund | X19: 28.1 | Y19: 0.0089 | Z19: =12631*X19 -> 354931.1
C20: 46101 | D20: 12602.65 | E20: 20392 | V20: 11 | W20: Investor Education And Protection Fund (IEPF) | X20: 0.36051 | Y20: 0.0001 | Z20: =12631*X20 -> 4553.6018
C23: 46098 | D23: 12993.55 | E23: 30535 | W23: Axis Bluechip Fund 28.10 0.89%
C24: 46097 | D24: 12753.3 | E24: 25175 | P24: Promoters | Q24: 0.5828
C25: 46094 | D25: 12588.45 | E25: 40288 | P25: FIIs | Q25: 0.1576
C26: 46093 | D26: 13016.1 | E26: 123556 | P26: DIIs | Q26: 0.2284
C27: 46091 | D27: 13870.05 | E27: 13374 | P27: Public & Govt | Q27: =3.04%+0.08% -> 0.0312
C28: 46090 | D28: 13504.45 | E28: 22884
C29: 46087 | D29: 14149.15 | E29: 12820
C30: 46086 | D30: 14416.35 | E30: 20274
C31: 46085 | D31: 14152.45 | E31: 24165
C32: 46083 | D32: 14380.6 | E32: 27046
C33: 46080 | D33: 14869.55 | E33: 25537
C34: 46079 | D34: 15213.05 | E34: 10032
C35: 46078 | D35: 15060.1 | E35: 14582
C36: 46077 | D36: 14924.4 | E36: 2696
C37: 46076 | D37: 15067.7 | E37: 8521
C38: 46073 | D38: 14987.55 | E38: 30817
C39: 46072 | D39: 14904 | E39: 3826
... C91: 45995 | D91: 15997.2 | E91: 12099
C92: 45994 | D92: 16083.75 | E92: 5515 | H92: 1 Mr. Hisashi Takeuchi, Managing Director & CEO | I92: 0.113 | J92: 32.86
C93: 45993 | D93: 16240.9 | E93: 13481 | H93: 2 Mr. Kenichiro Toyofuku, Director (Sustainability) | I93: 0.113 | J93: 24.37
C94: 45992 | D94: 16116 | E94: 5552 | H94: 3 Mr. Kazunari Yamaguchi, Director (Production) | I94: 0.113 | J94: 24.37
C95: 45989 | D95: 15894.1 | E95: 5599 | H95: 4 Mr. Sanjeev Grover, Company Secretary | I95: 0.1632 | J95: NA
C96: 45988 | D96: 15902.6 | E96: 12978 | H96: 5 Mr. Arnab Roy, Chief Financial Officer | I96: 0.1159 | J96: NA
C97: 45987 | D97: 16154.55 | E97: 6639
C98: 45986 | D98: 15882.95 | E98: 5654
...
